Workbook

Sheet Hypothèses
B1: HAVN STAYS — MODÈLE DE RENTABILITÉ
B2: Ton CA = tes 20% de commission + cleaning fees. Les 80% du proprio NE SONT PAS dans ce modèle.
B4: PARAMÈTRES VILLA (cellules jaunes = modifiables)
C5: Villa Moyenne | D5: Villa Premium | E5: Villa Luxe
B6: Tarif moyen par nuit (ADR) | C6: 2500 | D6: 5000 | E6: 8000
B7: Taux d'occupation | C7: 0.67 | D7: 0.67 | E7: 0.67
B8: → Nuits occupées / an | C8: =ROUND(365*C7,0) -> 245 | D8: =ROUND(365*D7,0) -> 245 | E8: =ROUND(365*E7,0) -> 245
B9: Durée moyenne séjour (nuits) | C9: 4.5 | D9: 5 | E9: 5.5
B10: → Nombre de réservations / an | C10: =ROUND(C8/C9,0) -> 54 | D10: =ROUND(D8/D9,0) -> 49 | E10: =ROUND(E8/E9,0) -> 45
B12: TES 2 SOURCES DE REVENU
B13: Commission sur location (TTC) | C13: 0.2
B14: Cleaning fee facturé au voyageur | C14: 115 | D14: fourchette 100-130 €
B15: Taux de change EUR → MAD | C15: 11
B16: → Cleaning fee en MAD | C16: =C14*C15 -> 1265
B17: Nb de ménages par réservation | C17: 1
B18: TVA sur services | C18: 0.2
B19: Taux CNSS employeur | C19: 0.266
B21: TES REVENUS PAR VILLA / AN
C22: Villa Moyenne | D22: Villa Premium | E22: Villa Luxe
B23: Commission TTC / an | C23: =C6*C8*$C$13 -> 122500 | D23: =D6*D8*$C$13 -> 245000 | E23: =E6*E8*$C$13 -> 392000
B24: Cleaning fees TTC / an | C24: =$C$16*$C$17*C10 -> 68310 | D24: =$C$16*$C$17*D10 -> 61985 | E24: =$C$16*$C$17*E10 -> 56925
B25: TOTAL REVENUS TTC / VILLA / AN | C25: =C23+C24 -> 190810 | D25: =D23+D24 -> 306985 | E25: =E23+E24 -> 448925
B26: (-) TVA | C26: =C25-C25/(1+$C$18) -> 31801.667 | D26: =D25-D25/(1+$C$18) -> 51164.167 | E26: =E25-E25/(1+$C$18) -> 74820.833
B27: TOTAL REVENUS HT / VILLA / AN | C27: =C25/(1+$C$18) -> 159008.33 | D27: =D25/(1+$C$18) -> 255820.83 | E27: =E25/(1+$C$18) -> 374104.17
B28: → par mois | C28: =C27/12 -> 13250.694 | D28: =D27/12 -> 21318.403 | E28: =E27/12 -> 31175.347
B30: TES CHARGES DIRECTES PAR VILLA
B31: Poste | C31: Par mois | D31: Par an | E31: Note
B32: Femme de ménage (1 par villa) | C32: 3500 | D32: =C32*12*(1+$C$19) -> 53172 | E32: + CNSS
B33: Matériel & produits ménage | C33: 1000 | D33: =C33*12 -> 12000
B34: Blanchisserie / laundry | C34: 1500 | D34: =C34*12 -> 18000
B35: Maintenance courante | C35: 1000 | D35: =C35*12 -> 12000
B36: Logiciels / villa (Hostaway, CRM...) | C36: 200 | D36: =C36*12 -> 2400 | E36: par villa
B37: TOTAL CHARGES DIRECTES / VILLA / AN | C37: =SUM(C32:C36) -> 7200 | D37: =SUM(D32:D36) -> 97572
B39: MARGE PAR VILLA (revenu HT − charges directes)
C40: Villa Moyenne | D40: Villa Premium | E40: Villa Luxe
B41: Revenu HT / an | C41: =C27 -> 159008.33 | D41: =D27 -> 255820.83 | E41: =E27 -> 374104.17
B42: (-) Charges directes / an | C42: =$D$37 -> 97572 | D42: =$D$37 -> 97572 | E42: =$D$37 -> 97572
B43: (=) MARGE PAR VILLA / AN | C43: =C41-C42 -> 61436.333 | D43: =D41-D42 -> 158248.83 | E43: =E41-E42 -> 276532.17
B44: → par mois | C44: =C43/12 -> 5119.6944 | D44: =D43/12 -> 13187.403 | E44: =E43/12 -> 23044.347
B46: TES CHARGES FIXES AGENCE (indépendantes du nb de villas)
...

Sheet Résultat
B1: TON RÉSULTAT NET
B2: CA = tes commissions (20%) + tes cleaning fees. Les 80% du propriétaire NE SONT PAS ici.
B4: TON PORTEFEUILLE (modifiable)
C5: 1 villa moyenne | D5: 1 villa premium | E5: 1 villa luxe | F5: 3 villas mix | G5: 5 villas mix
B6: Nb villas moyennes (ADR 2 500 MAD) | C6: 1 | D6: 0 | E6: 0 | F6: 1 | G6: 2
B7: Nb villas premium (ADR 5 000 MAD) | C7: 0 | D7: 1 | E7: 0 | F7: 1 | G7: 2
B8: Nb villas luxe (ADR 8 000 MAD) | C8: 0 | D8: 0 | E8: 1 | F8: 1 | G8: 1
B9: Total villas | C9: =C6+C7+C8 -> 1 | D9: =D6+D7+D8 -> 1 | E9: =E6+E7+E8 -> 1 | F9: =F6+F7+F8 -> 3 | G9: =G6+G7+G8 -> 5
B11: ① TON CA (par an)
B12: Commissions TTC (20% du loyer) | C12: =C6*Hypothèses!C23+C7*Hypothèses!D23+C8*Hypothèses!E23 -> 122500 | D12: =D6*Hypothèses!C23+D7*Hypothèses!D23+D8*Hypothèses!E23 -> 245000 | E12: =E6*Hypothèses!C23+E7*Hypothèses!D23+E8*Hypothèses!E23 -> 392000 | F12: =F6*Hypothèses!C23+F7*Hypothèses!D23+F8*Hypothèses!E23 -> 759500 | G12: =G6*Hypothèses!C23+G7*Hypothèses!D23+G8*Hypothèses!E23 -> 1127000
B13: Cleaning fees TTC | C13: =C6*Hypothèses!C24+C7*Hypothèses!D24+C8*Hypothèses!E24 -> 68310 | D13: =D6*Hypothèses!C24+D7*Hypothèses!D24+D8*Hypothèses!E24 -> 61985 | E13: =E6*Hypothèses!C24+E7*Hypothèses!D24+E8*Hypothèses!E24 -> 56925 | F13: =F6*Hypothèses!C24+F7*Hypothèses!D24+F8*Hypothèses!E24 -> 187220 | G13: =G6*Hypothèses!C24+G7*Hypothèses!D24+G8*Hypothèses!E24 -> 317515
B14: TOTAL REVENUS TTC | C14: =C12+C13 -> 190810 | D14: =D12+D13 -> 306985 | E14: =E12+E13 -> 448925 | F14: =F12+F13 -> 946720 | G14: =G12+G13 -> 1444515
B15: (-) TVA | C15: =C14-C14/(1+Hypothèses!$C$18) -> 31801.667 | D15: =D14-D14/(1+Hypothèses!$C$18) -> 51164.167 | E15: =E14-E14/(1+Hypothèses!$C$18) -> 74820.833 | F15: =F14-F14/(1+Hypothèses!$C$18) -> 157786.67 | G15: =G14-G14/(1+Hypothèses!$C$18) -> 240752.5
B16: TON CA HORS TAXE | C16: =C14-C15 -> 159008.33 | D16: =D14-D15 -> 255820.83 | E16: =E14-E15 -> 374104.17 | F16: =F14-F15 -> 788933.33 | G16: =G14-G15 -> 1203762.5
B17: → par mois | C17: =C16/12 -> 13250.694 | D17: =D16/12 -> 21318.403 | E17: =E16/12 -> 31175.347 | F17: =F16/12 -> 65744.444 | G17: =G16/12 -> 100313.54
B19: ② TES CHARGES (par an)
B20: Charges directes villas (ménage, linge, maint., logiciels × nb villas) | C20: =C9*Hypothèses!$D$37 -> 97572 | D20: =D9*Hypothèses!$D$37 -> 97572 | E20: =E9*Hypothèses!$D$37 -> 97572 | F20: =F9*Hypothèses!$D$37 -> 292716 | G20: =G9*Hypothèses!$D$37 -> 487860
B21: Charges fixes agence (salaires, bureau, marketing...) | C21: =Hypothèses!$D$59 -> 578592 | D21: =Hypothèses!$D$59 -> 578592 | E21: =Hypothèses!$D$59 -> 578592 | F21: =Hypothèses!$D$59 -> 578592 | G21: =Hypothèses!$D$59 -> 578592
B22: TOTAL CHARGES | C22: =C20+C21 -> 676164 | D22: =D20+D21 -> 676164 | E22: =E20+E21 -> 676164 | F22: =F20+F21 -> 871308 | G22: =G20+G21 -> 1066452
B23: → par mois | C23: =C22/12 -> 56347 | D23: =D22/12 -> 56347 | E23: =E22/12 -> 56347 | F23: =F22/12 -> 72609 | G23: =G22/12 -> 88871
B25: ③ RÉSULTAT = CA HT − CHARGES (par an)
B26: Résultat avant impôt | C26: =C16-C22 -> -517155.67 | D26: =D16-D22 -> -420343.17 | E26: =E16-E22 -> -302059.83 | F26: =F16-F22 -> -82374.667 | G26: =G16-G22 -> 137310.5
B27: (-) Impôt sur les Sociétés (IS) | C27: =IF(C26<=0,0,IF(C26<=300000,C26*0.1,IF(C26<=1000000,30000+(C26-300000)*0.2,30000+140000+(C26-1000000)*0.31))) -> 0 | D27: =IF(D26<=0,0,IF(D26<=300000,D26*0.1,IF(D26<=1000000,30000+(D26-300000)*0.2,30000+140000+(D26-1000000)*0.31))) -> 0 | E27: =IF(E26<=0,0,IF(E26<=300000,E26*0.1,IF(E26<=1000000,30000+(E26-300000)*0.2,30000+140000+(E26-1000000)*0.31))) -> 0 | F27: =IF(F26<=0,0,IF(F26<=300000,F26*0.1,IF(F26<=1000000,30000+(F26-300000)*0.2,30000+140000+(F26-1000000)*0.31))) -> 0 | G27: =IF(G26<=0,0,IF(G26<=300000,G26*0.1,IF(G26<=1000000,30000+(G26-300000)*0.2,30000+140000+(G26-1000000)*0.31))) -> 13731.05
B29: RÉSULTAT NET APRÈS IMPÔT | C29: =C26-C27 -> -517155.67 | D29: =D26-D27 -> -420343.17 | E29: =E26-E27 -> -302059.83 | F29: =F26-F27 -> -82374.667 | G29: =G26-G27 -> 123579.45
B30: → par mois | C30: =C29/12 -> -43096.306 | D30: =D29/12 -> -35028.597 | E30: =E29/12 -> -25171.653 | F30: =F29/12 -> -6864.5556 | G30: =G29/12 -> 10298.288
B31: RENTABLE ? | C31: =IF(C29>0,"✅ OUI","❌ NON") -> ❌ NON | D31: =IF(D29>0,"✅ OUI","❌ NON") -> ❌ NON | E31: =IF(E29>0,"✅ OUI","❌ NON") -> ❌ NON | F31: =IF(F29>0,"✅ OUI","❌ NON") -> ❌ NON | G31: =IF(G29>0,"✅ OUI","❌ NON") -> ✅ OUI
B33: ④ INDICATEURS
B34: Marge nette (% du CA HT) | C34: =IF(C16>0,C29/C16,0) -> -3.2523809 | D34: =IF(D16>0,D29/D16,0) -> -1.6431155 | E34: =IF(E16>0,E29/E16,0) -> -0.80742173 | F34: =IF(F16>0,F29/F16,0) -> -0.10441271 | G34: =IF(G16>0,G29/G16,0) -> 0.10266099
B36: Point mort en villas premium | C36: =IF(Hypothèses!D43>0,Hypothèses!$D$59/Hypothèses!D43,0) -> 3.6562165 | D36: pour couvrir les charges fixes
B37: Point mort en villas luxe | C37: =IF(Hypothèses!E43>0,Hypothèses!$D$59/Hypothèses!E43,0) -> 2.0923136 | D37: pour couvrir les charges fixes
